#include <exception>
#include <iostream>

int main(int, char *[])
try
{
    return 0;
}
catch (const std::exception &e)
{
    std::cerr << "Exception: " << e.what() << "\n";
    return 1;
}
catch (...)
{
    std::cerr << "Unknown exception\n";
    return 1;
}